Loading module miniconda version 23.1.0-1
Traceback (most recent call last):
  File "linear_probing.py", line 244, in <module>
    main(config)
  File "linear_probing.py", line 162, in main
    probing_df = pd.read_csv(eval_data_dir+eval_data_file_name+'_'+str(model_name)+'.csv')
  File "/nvme_scratch1/cjh86475/conda_envs/aiml_active_learning_almo_all/lib/python3.8/site-packages/pandas/util/_decorators.py", line 211, in wrapper
    return func(*args, **kwargs)
  File "/nvme_scratch1/cjh86475/conda_envs/aiml_active_learning_almo_all/lib/python3.8/site-packages/pandas/util/_decorators.py", line 331, in wrapper
    return func(*args, **kwargs)
  File "/nvme_scratch1/cjh86475/conda_envs/aiml_active_learning_almo_all/lib/python3.8/site-packages/pandas/io/parsers/readers.py", line 950, in read_csv
    return _read(filepath_or_buffer, kwds)
  File "/nvme_scratch1/cjh86475/conda_envs/aiml_active_learning_almo_all/lib/python3.8/site-packages/pandas/io/parsers/readers.py", line 605, in _read
    parser = TextFileReader(filepath_or_buffer, **kwds)
  File "/nvme_scratch1/cjh86475/conda_envs/aiml_active_learning_almo_all/lib/python3.8/site-packages/pandas/io/parsers/readers.py", line 1442, in __init__
    self._engine = self._make_engine(f, self.engine)
  File "/nvme_scratch1/cjh86475/conda_envs/aiml_active_learning_almo_all/lib/python3.8/site-packages/pandas/io/parsers/readers.py", line 1735, in _make_engine
    self.handles = get_handle(
  File "/nvme_scratch1/cjh86475/conda_envs/aiml_active_learning_almo_all/lib/python3.8/site-packages/pandas/io/common.py", line 856, in get_handle
    handle = open(
FileNotFoundError: [Errno 2] No such file or directory: '/hdd_scratch2/cjh86475/channel_agnostic_model/experiment_outputs/model_evaluations/maeaggregate_data_mae.csv'
Traceback (most recent call last):
  File "run_linear_pipeline.py", line 9, in <module>
    subprocess.check_call(['python', script, '-c', 'config.yaml'])
  File "/nvme_scratch1/cjh86475/conda_envs/aiml_active_learning_almo_all/lib/python3.8/subprocess.py", line 364, in check_call
    raise CalledProcessError(retcode, cmd)
subprocess.CalledProcessError: Command '['python', 'linear_probing.py', '-c', 'config.yaml']' returned non-zero exit status 1.
